Workbook

Sheet Input Data
A1: INPUT DATA – PENERIMAAN MATERIAL PERSEDIAAN DAN NON-PERSEDIAAN DI WAREHOUSE
A2: Sumber data untuk sheet BASTB (Lampiran 3), LHPB (Lampiran 5) dan Form Perhitungan Denda Keterlambatan (Lampiran 6) – TKO No. B7-084/PHE52000/2025-S9. Isi hanya sel berwarna krem; sel putih terhitung otomatis.
A4: A. DOKUMEN PEMBELIAN & VENDOR | H4: B. PENERIMAAN & NOMOR DOKUMEN
A5: Nomor PO/RO | H5: Judul Pekerjaan / Perihal
A6: Nomor Kontrak/OA | H6: Warehouse / Titik Penerimaan
A7: Jangka Waktu Kontrak | H7: Tanggal Penerimaan Barang
A8: Delivery Date (sesuai PO/RO) | H8: Tanggal Pemeriksaan
A9: Tipe Material | H9: Pengawas Pekerjaan/Pengadaan
A10: Partial Quantity diizinkan | H10: Nomor GR
A11: Vendor Commitment | H11: Tanggal GR
A12: ID Vendor | H12: Nomor BAST
A13: Nama Vendor | H13: Tanggal BAST
A14: NPWP/NITKU | H14: Nomor LHPB
A15: Email Vendor | H15: Nomor Form Denda
A16: Nomor Telp Vendor
A17: Entitas Buyer | D17: PT Pertamina EP Field Rantau | H17: Ringkasan (otomatis)
A18: Tarif denda per hari keterlambatan | D18: 0.001 | H18: Jumlah item | J18: =IF(COUNTA(D23:D32)=0,"",COUNTA(D23:D32)) -> 2
A19: Batas maksimum denda | D19: 0.05 | H19: Status penyerahan | J19: =IF(COUNT(M23:M32)=0,"",IF(MAX(M23:M32)>0,"terlambat","tidak terlambat"))
H20: Total denda (IDR) | J20: ='Denda Keterlambatan'!J59 -> #VALUE!
A21: C. DATA MATERIAL (maksimal 10 item per dokumen)
A22: No | B22: Line No. | C22: KIMAP / Nomor Material | D22: Deskripsi Material | E22: Satuan | F22: Qty PO/RO | G22: Qty Diterima | H22: Harga Satuan (IDR) | I22: Jumlah Harga PO/RO (IDR) | J22: % TKDN | K22: Tgl Jatuh Tempo (jika beda per item) | L22: Tgl Penerimaan (jika beda per item) | M22: Hari Terlambat | N22: Status Pemeriksaan | O22: Catatan
A23: 1 | I23: =IF(OR(F23="",H23=""),"",F23*H23) -> 131730000 | M23: =IF(D23="","",IF(OR(IF(K23="",$D$8,K23)="",IF(L23="",$J$7,L23)=""),"",MAX(0,IF(L23="",$J$7,L23)-IF(K23="",$D$8,K23)))) -> #VALUE!
A24: 2 | I24: =IF(OR(F24="",H24=""),"",F24*H24) -> 153000000 | M24: =IF(D24="","",IF(OR(IF(K24="",$D$8,K24)="",IF(L24="",$J$7,L24)=""),"",MAX(0,IF(L24="",$J$7,L24)-IF(K24="",$D$8,K24)))) -> #VALUE!
A25: 3 | I25: =IF(OR(F25="",H25=""),"",F25*H25) | M25: =IF(D25="","",IF(OR(IF(K25="",$D$8,K25)="",IF(L25="",$J$7,L25)=""),"",MAX(0,IF(L25="",$J$7,L25)-IF(K25="",$D$8,K25))))
A26: 4 | I26: =IF(OR(F26="",H26=""),"",F26*H26) | M26: =IF(D26="","",IF(OR(IF(K26="",$D$8,K26)="",IF(L26="",$J$7,L26)=""),"",MAX(0,IF(L26="",$J$7,L26)-IF(K26="",$D$8,K26))))
A27: 5 | I27: =IF(OR(F27="",H27=""),"",F27*H27) | M27: =IF(D27="","",IF(OR(IF(K27="",$D$8,K27)="",IF(L27="",$J$7,L27)=""),"",MAX(0,IF(L27="",$J$7,L27)-IF(K27="",$D$8,K27))))
A28: 6 | I28: =IF(OR(F28="",H28=""),"",F28*H28) | M28: =IF(D28="","",IF(OR(IF(K28="",$D$8,K28)="",IF(L28="",$J$7,L28)=""),"",MAX(0,IF(L28="",$J$7,L28)-IF(K28="",$D$8,K28))))
A29: 7 | I29: =IF(OR(F29="",H29=""),"",F29*H29) | M29: =IF(D29="","",IF(OR(IF(K29="",$D$8,K29)="",IF(L29="",$J$7,L29)=""),"",MAX(0,IF(L29="",$J$7,L29)-IF(K29="",$D$8,K29))))
A30: 8 | I30: =IF(OR(F30="",H30=""),"",F30*H30) | M30: =IF(D30="","",IF(OR(IF(K30="",$D$8,K30)="",IF(L30="",$J$7,L30)=""),"",MAX(0,IF(L30="",$J$7,L30)-IF(K30="",$D$8,K30))))
A31: 9 | I31: =IF(OR(F31="",H31=""),"",F31*H31) | M31: =IF(D31="","",IF(OR(IF(K31="",$D$8,K31)="",IF(L31="",$J$7,L31)=""),"",MAX(0,IF(L31="",$J$7,L31)-IF(K31="",$D$8,K31))))
A32: 10 | I32: =IF(OR(F32="",H32=""),"",F32*H32) | M32: =IF(D32="","",IF(OR(IF(K32="",$D$8,K32)="",IF(L32="",$J$7,L32)=""),"",MAX(0,IF(L32="",$J$7,L32)-IF(K32="",$D$8,K32))))
A33: Total | I33: =SUM(I23:I32) -> 284730000
A35: PETUNJUK PENGISIAN (di luar area cetak)
A36: 1. Semua data PO/RO, vendor, penerimaan dan material cukup diisi di sheet ini; sheet BASTB, LHPB dan Denda Keterlambatan otomatis mengambil datanya.
A37: 2. Tgl Jatuh Tempo dan Tgl Penerimaan per item boleh dikosongkan – jika kosong dipakai Delivery Date (bagian A) dan Tanggal Penerimaan Barang (bagian B). Hari Terlambat = Tgl Penerimaan − Tgl Jatuh Tempo (hari kalender).
A38: 3. BASTB memakai Qty Diterima; LHPB menampilkan Qty PO/RO dan Qty Diterima; denda dihitung dari Jumlah Harga PO/RO × % keterlambatan.
A39: 4. Tarif 0,1%/hari dan maksimum 5% hanya nilai awal – wajib disesuaikan dengan klausul denda OA/RO/PO.
A40: 5. Contoh baris: Line No. 10 · KIMAP 1000123456 · Gate Valve 2" 600# · EA · Qty PO 4 · Qty Diterima 4 · Harga 2500000 · TKDN 25% · Status Diterima.

Sheet BASTB
A1: Lampiran 3 – TKO No. B7-084/PHE52000/2025-S9-F002 · Revisi Ke-0
A2: PERTAMINA HULU ENERGI | C2: BERITA ACARA SERAH TERIMA BARANG
A5: Nomor BAST | C5: =IF('Input Data'!$J$12="","",'Input Data'!$J$12) -> 0041/BASTB/10/2026
A6: Tanggal BAST | C6: =IF('Input Data'!$J$13="","",'Input Data'!$J$13) -> NaN
A7: Nomor Kontrak | C7: =IF('Input Data'!$D$6="","",'Input Data'!$D$6) -> 4720000471
A8: Jangka Waktu Kontrak | C8: =IF('Input Data'!$D$7="","",'Input Data'!$D$7) -> 2 (DUA) TAHUN
A9: Nomor PO | C9: =IF('Input Data'!$D$5="","",'Input Data'!$D$5) -> 4300096306
A10: NPWP/NITKU | C10: =IF('Input Data'!$D$14="","",'Input Data'!$D$14) -> 02.827.099.9-216.000
A11: Nama Vendor | C11: =IF('Input Data'!$D$13="","",'Input Data'!$D$13) -> PT. INTI PERKASA TEKNIK
A12: Email Vendor | C12: =IF('Input Data'!$D$15="","",'Input Data'!$D$15) -> iptek@indo.net.id
A13: Nomor Telp Vendor | C13: =IF('Input Data'!$D$16="","",'Input Data'!$D$16) -> 0761-839853
A14: Entitas Buyer | C14: =IF('Input Data'!$D$17="","",'Input Data'!$D$17) -> PT Pertamina EP Field Rantau
A15: Perihal | C15: =IF('Input Data'!$J$5="","",'Input Data'!$J$5) -> PEMENUHAN MATERIAL CUP PACKER PT PERTAMINA EP ZONA 1 FIELD RANTAU REF OA 4720000471
A17: Pernyataan meliputi :
A18: ="1. Pada tanggal "&IF('Input Data'!$J$7="","[...]",DAY('Input Data'!$J$7)&" "&CHOOSE(MONTH('Input Data'!$J$7),"Januari","Februari","Maret","April","Mei","Juni","Juli","Agustus","September","Oktober","November","Desember")&" "&YEAR('Input Data'!$J$7))&" telah dilakukan penyerahan pekerjaan sebagai berikut:" -> #VALUE!
A19: No. | B19: Deskripsi Barang | C19: Kuantitas | D19: KIMAP | E19: Harga Satuan (IDR) | F19: Jumlah (IDR)
A20: =IF('Input Data'!D23="","",'Input Data'!A23) -> 1 | B20: =IF('Input Data'!D23="","",'Input Data'!D23) -> CUP PACKER, 7" X 2.7/8", 22-24# | C20: =IF('Input Data'!G23="","",'Input Data'!G23) -> 2 | D20: =IF('Input Data'!C23="","",'Input Data'!C23) -> B134900003 | E20: =IF('Input Data'!H23="","",'Input Data'!H23) -> 65865000 | F20: =IF(OR(C20="",E20=""),"",C20*E20) -> 131730000
A21: =IF('Input Data'!D24="","",'Input Data'!A24) -> 2 | B21: =IF('Input Data'!D24="","",'Input Data'!D24) -> PCKR,REDRESS KIT,CUP,7,J55,5000,300 | C21: =IF('Input Data'!G24="","",'Input Data'!G24) -> 18 | D21: =IF('Input Data'!C24="","",'Input Data'!C24) -> Z66210004900 | E21: =IF('Input Data'!H24="","",'Input Data'!H24) -> 8500000 | F21: =IF(OR(C21="",E21=""),"",C21*E21) -> 153000000
A22: =IF('Input Data'!D25="","",'Input Data'!A25) | B22: =IF('Input Data'!D25="","",'Input Data'!D25) | C22: =IF('Input Data'!G25="","",'Input Data'!G25) | D22: =IF('Input Data'!C25="","",'Input Data'!C25) | E22: =IF('Input Data'!H25="","",'Input Data'!H25) | F22: =IF(OR(C22="",E22=""),"",C22*E22)
A23: =IF('Input Data'!D26="","",'Input Data'!A26) | B23: =IF('Input Data'!D26="","",'Input Data'!D26) | C23: =IF('Input Data'!G26="","",'Input Data'!G26) | D23: =IF('Input Data'!C26="","",'Input Data'!C26) | E23: =IF('Input Data'!H26="","",'Input Data'!H26) | F23: =IF(OR(C23="",E23=""),"",C23*E23)
A24: =IF('Input Data'!D27="","",'Input Data'!A27) | B24: =IF('Input Data'!D27="","",'Input Data'!D27) | C24: =IF('Input Data'!G27="","",'Input Data'!G27) | D24: =IF('Input Data'!C27="","",'Input Data'!C27) | E24: =IF('Input Data'!H27="","",'Input Data'!H27) | F24: =IF(OR(C24="",E24=""),"",C24*E24)
A25: =IF('Input Data'!D28="","",'Input Data'!A28) | B25: =IF('Input Data'!D28="","",'Input Data'!D28) | C25: =IF('Input Data'!G28="","",'Input Data'!G28) | D25: =IF('Input Data'!C28="","",'Input Data'!C28) | E25: =IF('Input Data'!H28="","",'Input Data'!H28) | F25: =IF(OR(C25="",E25=""),"",C25*E25)
A26: =IF('Input Data'!D29="","",'Input Data'!A29) | B26: =IF('Input Data'!D29="","",'Input Data'!D29) | C26: =IF('Input Data'!G29="","",'Input Data'!G29) | D26: =IF('Input Data'!C29="","",'Input Data'!C29) | E26: =IF('Input Data'!H29="","",'Input Data'!H29) | F26: =IF(OR(C26="",E26=""),"",C26*E26)
A27: =IF('Input Data'!D30="","",'Input Data'!A30) | B27: =IF('Input Data'!D30="","",'Input Data'!D30) | C27: =IF('Input Data'!G30="","",'Input Data'!G30) | D27: =IF('Input Data'!C30="","",'Input Data'!C30) | E27: =IF('Input Data'!H30="","",'Input Data'!H30) | F27: =IF(OR(C27="",E27=""),"",C27*E27)
A28: =IF('Input Data'!D31="","",'Input Data'!A31) | B28: =IF('Input Data'!D31="","",'Input Data'!D31) | C28: =IF('Input Data'!G31="","",'Input Data'!G31) | D28: =IF('Input Data'!C31="","",'Input Data'!C31) | E28: =IF('Input Data'!H31="","",'Input Data'!H31) | F28: =IF(OR(C28="",E28=""),"",C28*E28)
A29: =IF('Input Data'!D32="","",'Input Data'!A32) | B29: =IF('Input Data'!D32="","",'Input Data'!D32) | C29: =IF('Input Data'!G32="","",'Input Data'!G32) | D29: =IF('Input Data'!C32="","",'Input Data'!C32) | E29: =IF('Input Data'!H32="","",'Input Data'!H32) | F29: =IF(OR(C29="",E29=""),"",C29*E29)
A30: Total | F30: =SUM(F20:F29) -> 284730000
A31: ="Dimana jumlah barang tersebut telah sesuai dengan persyaratan yang ada pada Release Order (RO) dan/atau Purchase Order (PO) No. "&IF($C$9="","________",$C$9) -> Dimana jumlah barang tersebut telah sesuai dengan persyaratan yang ada pada Release Order (RO) dan/atau Purchase Order (PO) No. 4300096306
A32: ="2. Telah dilakukan pemeriksaan di Warehouse "&IF('Input Data'!$J$6="","________",'Input Data'!$J$6)&" pada tanggal "&IF('Input Data'!$J$8="","[...]",DAY('Input Data'!$J$8)&" "&CHOOSE(MONTH('Input Data'!$J$8),"Januari","Februari","Maret","April","Mei","Juni","Juli","Agustus","September","Oktober","November","Desember")&" "&YEAR('Input Data'!$J$8))&", dimana dinyatakan bahwa barang tersebut telah diserahterimakan dalam kondisi sesuai dengan persyaratan yang ada pada Release Order (RO) dan/atau Purchase Order (PO) No. "&IF($C$9="","________",$C$9)&"." -> #VALUE!
A33: ="3. Berdasarkan tanggal penyerahan yang dinyatakan di poin 1 diatas, kami menyatakan penyerahan barang tersebut "&IF('Input Data'!$J$19="","terlambat/tidak terlambat",'Input Data'!$J$19)&" dengan persyaratan yang ada pada Release Order (RO) dan/atau Purchase Order (PO) No. "&IF($C$9="","________",$C$9)&". Dengan didukung oleh dokumen pendukung pelaksanaan pekerjaan sebagaimana disyaratkan dalam kontrak." -> 3. Berdasarkan tanggal penyerahan yang dinyatakan di poin 1 diatas, kami menyatakan penyerahan barang tersebut terlambat/tidak terlambat dengan persyaratan yang ada pada Release Order (RO) dan/atau Purchase Order (PO) No. 4300096306. Dengan didukung oleh dokumen pendukung pelaksanaan pekerjaan sebagaimana disyaratkan dalam kontrak.
A34: ="4. Dengan menandatangani BAST ini, maka "&IF($C$11="","Vendor",$C$11)&" dan "&IF($C$14="","PT Pertamina ____",$C$14)&" menyatakan bahwa:" -> 4. Dengan menandatangani BAST ini, maka PT. INTI PERKASA TEKNIK dan PT Pertamina EP Field Rantau menyatakan bahwa:
A35: ="a. Dokumen ini menjadi acuan utama bagi "&IF($C$11="","Vendor",$C$11)&" dalam melakukan penagihan kepada "&IF($C$14="","PT Pertamina ____",$C$14)&" dan diakui oleh masing-masing pihak keabsahannya tanpa memerlukan tandatangan basah di dokumen ini oleh masing-masing pihak." -> a. Dokumen ini menjadi acuan utama bagi PT. INTI PERKASA TEKNIK dalam melakukan penagihan kepada PT Pertamina EP Field Rantau dan diakui oleh masing-masing pihak keabsahannya tanpa memerlukan tandatangan basah di dokumen ini oleh masing-masing pihak.
A36: ="b. Segala kewajiban "&IF($C$11="","Vendor",$C$11)&" atas pekerjaan dengan nomor PO "&IF($C$9="","________",$C$9)&", BAST sudah selesai dilakukan sepenuhnya dan diterima baik oleh "&IF($C$14="","PT Pertamina ____",$C$14)&"." -> b. Segala kewajiban PT. INTI PERKASA TEKNIK atas pekerjaan dengan nomor PO 4300096306, BAST sudah selesai dilakukan sepenuhnya dan diterima baik oleh PT Pertamina EP Field Rantau.
A37: ="c. "&IF($C$11="","Vendor",$C$11)&" selaku Penyedia Barang/Jasa telah menyampaikan seluruh dokumen pendukung terkait pelaksanaan pekerjaan sebagaimana dipersyaratkan dalam kontrak." -> c. PT. INTI PERKASA TEKNIK selaku Penyedia Barang/Jasa telah menyampaikan seluruh dokumen pendukung terkait pelaksanaan pekerjaan sebagaimana dipersyaratkan dalam kontrak.
A38: ="d. "&IF($C$14="","PT Pertamina ____",$C$14)&" telah melakukan pemeriksaan atas seluruh dokumen pendukung yang telah disampaikan oleh "&IF($C$11="","Vendor",$C$11)&"." -> d. PT Pertamina EP Field Rantau telah melakukan pemeriksaan atas seluruh dokumen pendukung yang telah disampaikan oleh PT. INTI PERKASA TEKNIK.
A39: ="e. Dokumen Berita Acara ini menjadi salah satu dasar pembayaran tagihan Penyedia Barang/Jasa oleh "&IF($C$14="","PT Pertamina ____",$C$14)&"." -> e. Dokumen Berita Acara ini menjadi salah satu dasar pembayaran tagihan Penyedia Barang/Jasa oleh PT Pertamina EP Field Rantau.
A41: =IF($C$14="","PT Pertamina ____",$C$14) -> PT Pertamina EP Field Rantau | D41: =IF($C$11="","Vendor",$C$11) -> PT. INTI PERKASA TEKNIK
A50: PETUNJUK PENGISIAN (di luar area cetak)
A51: 1. Seluruh data di sheet ini otomatis diambil dari sheet Input Data. Yang diisi di sini hanya sel krem: Nama Pejabat Berwenang (baris pertama) dan Jabatan (baris kedua).
A52: 2. Kuantitas memakai Qty Diterima. Status terlambat/tidak terlambat pada poin 3 mengikuti kolom Hari Terlambat di Input Data.
...

Sheet LHPB
A1: Lampiran 5 – TKO No. B7-084/PHE52000/2025-S9-F004 · Revisi Ke-0
A2: PERTAMINA HULU ENERGI | D2: LAPORAN HASIL PEMERIKSAAN BARANG (LHPB)
A5: Nomor | D5: =IF('Input Data'!$J$14="","",'Input Data'!$J$14) -> 0041/LHPB/10/2026
A6: Tanggal Pemeriksaan | D6: =IF('Input Data'!$J$8="","",'Input Data'!$J$8) -> NaN
A7: Lokasi Pemeriksaan | D7: =IF('Input Data'!$J$6="","",'Input Data'!$J$6) -> Warehouse Field Rantau
A8: Pengawas Pekerjaan/Pengadaan | D8: =IF('Input Data'!$J$9="","",'Input Data'!$J$9) -> Officer SCM Support & Receiving Rantau
A9: Judul Pekerjaan | D9: =IF('Input Data'!$J$5="","",'Input Data'!$J$5) -> PEMENUHAN MATERIAL CUP PACKER PT PERTAMINA EP ZONA 1 FIELD RANTAU REF OA 4720000471
A10: Jumlah Item | D10: =IF('Input Data'!$J$18="","",'Input Data'!$J$18&" item") -> 2 item
A12: BERDASARKAN
A13: Nomor PO/RO | D13: =IF('Input Data'!$D$5="","",'Input Data'!$D$5) -> 4300096306
A14: Nomor OA/Kontrak | D14: =IF('Input Data'!$D$6="","",'Input Data'!$D$6) -> 4720000471
A15: Delivery Date | D15: =IF('Input Data'!$D$8="","",'Input Data'!$D$8) -> NaN
A16: Tipe : | D16: =IF('Input Data'!$D$9="Persediaan","✓","") | E16: Persediaan | G16: =IF('Input Data'!$D$9="Non Persediaan","✓","") -> ✓ | H16: Non Persediaan | I16: =IF('Input Data'!$D$10="Ya","✓","") -> ✓ | J16: Partial Quantity
A17: Vendor Commitment : | D17: =IF('Input Data'!$D$11="Full Delivery","✓","") | E17: Full Delivery | G17: =IF('Input Data'!$D$11="Partial Delivery","✓","") -> ✓ | H17: Partial Delivery
A21: No | B21: Nomor Material | C21: Deskripsi Material | D21: Qty PO/RO | E21: Satuan | F21: Qty Diterima | G21: % TKDN | H21: Status Pemeriksaan | J21: Catatan
H22: Diterima | I22: Ditolak
A23: =IF('Input Data'!D23="","",'Input Data'!A23) -> 1 | B23: =IF('Input Data'!C23="","",'Input Data'!C23) -> B134900003 | C23: =IF('Input Data'!D23="","",'Input Data'!D23) -> CUP PACKER, 7" X 2.7/8", 22-24# | D23: =IF('Input Data'!F23="","",'Input Data'!F23) -> 2 | E23: =IF('Input Data'!E23="","",'Input Data'!E23) -> PCS | F23: =IF('Input Data'!G23="","",'Input Data'!G23) -> 2 | G23: =IF('Input Data'!J23="","",'Input Data'!J23) -> 55,41% | H23: =IF('Input Data'!N23="Diterima","✓","") -> ✓ | I23: =IF('Input Data'!N23="Ditolak","✓","") | J23: =IF('Input Data'!O23="","",'Input Data'!O23)
A24: =IF('Input Data'!D24="","",'Input Data'!A24) -> 2 | B24: =IF('Input Data'!C24="","",'Input Data'!C24) -> Z66210004900 | C24: =IF('Input Data'!D24="","",'Input Data'!D24) -> PCKR,REDRESS KIT,CUP,7,J55,5000,300 | D24: =IF('Input Data'!F24="","",'Input Data'!F24) -> 18 | E24: =IF('Input Data'!E24="","",'Input Data'!E24) -> PCS | F24: =IF('Input Data'!G24="","",'Input Data'!G24) -> 18 | G24: =IF('Input Data'!J24="","",'Input Data'!J24) -> 55,41% | H24: =IF('Input Data'!N24="Diterima","✓","") -> ✓ | I24: =IF('Input Data'!N24="Ditolak","✓","") | J24: =IF('Input Data'!O24="","",'Input Data'!O24)
A25: =IF('Input Data'!D25="","",'Input Data'!A25) | B25: =IF('Input Data'!C25="","",'Input Data'!C25) | C25: =IF('Input Data'!D25="","",'Input Data'!D25) | D25: =IF('Input Data'!F25="","",'Input Data'!F25) | E25: =IF('Input Data'!E25="","",'Input Data'!E25) | F25: =IF('Input Data'!G25="","",'Input Data'!G25) | G25: =IF('Input Data'!J25="","",'Input Data'!J25) | H25: =IF('Input Data'!N25="Diterima","✓","") | I25: =IF('Input Data'!N25="Ditolak","✓","") | J25: =IF('Input Data'!O25="","",'Input Data'!O25)
A26: =IF('Input Data'!D26="","",'Input Data'!A26) | B26: =IF('Input Data'!C26="","",'Input Data'!C26) | C26: =IF('Input Data'!D26="","",'Input Data'!D26) | D26: =IF('Input Data'!F26="","",'Input Data'!F26) | E26: =IF('Input Data'!E26="","",'Input Data'!E26) | F26: =IF('Input Data'!G26="","",'Input Data'!G26) | G26: =IF('Input Data'!J26="","",'Input Data'!J26) | H26: =IF('Input Data'!N26="Diterima","✓","") | I26: =IF('Input Data'!N26="Ditolak","✓","") | J26: =IF('Input Data'!O26="","",'Input Data'!O26)
A27: =IF('Input Data'!D27="","",'Input Data'!A27) | B27: =IF('Input Data'!C27="","",'Input Data'!C27) | C27: =IF('Input Data'!D27="","",'Input Data'!D27) | D27: =IF('Input Data'!F27="","",'Input Data'!F27) | E27: =IF('Input Data'!E27="","",'Input Data'!E27) | F27: =IF('Input Data'!G27="","",'Input Data'!G27) | G27: =IF('Input Data'!J27="","",'Input Data'!J27) | H27: =IF('Input Data'!N27="Diterima","✓","") | I27: =IF('Input Data'!N27="Ditolak","✓","") | J27: =IF('Input Data'!O27="","",'Input Data'!O27)
A28: =IF('Input Data'!D28="","",'Input Data'!A28) | B28: =IF('Input Data'!C28="","",'Input Data'!C28) | C28: =IF('Input Data'!D28="","",'Input Data'!D28) | D28: =IF('Input Data'!F28="","",'Input Data'!F28) | E28: =IF('Input Data'!E28="","",'Input Data'!E28) | F28: =IF('Input Data'!G28="","",'Input Data'!G28) | G28: =IF('Input Data'!J28="","",'Input Data'!J28) | H28: =IF('Input Data'!N28="Diterima","✓","") | I28: =IF('Input Data'!N28="Ditolak","✓","") | J28: =IF('Input Data'!O28="","",'Input Data'!O28)
A29: =IF('Input Data'!D29="","",'Input Data'!A29) | B29: =IF('Input Data'!C29="","",'Input Data'!C29) | C29: =IF('Input Data'!D29="","",'Input Data'!D29) | D29: =IF('Input Data'!F29="","",'Input Data'!F29) | E29: =IF('Input Data'!E29="","",'Input Data'!E29) | F29: =IF('Input Data'!G29="","",'Input Data'!G29) | G29: =IF('Input Data'!J29="","",'Input Data'!J29) | H29: =IF('Input Data'!N29="Diterima","✓","") | I29: =IF('Input Data'!N29="Ditolak","✓","") | J29: =IF('Input Data'!O29="","",'Input Data'!O29)
A30: =IF('Input Data'!D30="","",'Input Data'!A30) | B30: =IF('Input Data'!C30="","",'Input Data'!C30) | C30: =IF('Input Data'!D30="","",'Input Data'!D30) | D30: =IF('Input Data'!F30="","",'Input Data'!F30) | E30: =IF('Input Data'!E30="","",'Input Data'!E30) | F30: =IF('Input Data'!G30="","",'Input Data'!G30) | G30: =IF('Input Data'!J30="","",'Input Data'!J30) | H30: =IF('Input Data'!N30="Diterima","✓","") | I30: =IF('Input Data'!N30="Ditolak","✓","") | J30: =IF('Input Data'!O30="","",'Input Data'!O30)
A31: =IF('Input Data'!D31="","",'Input Data'!A31) | B31: =IF('Input Data'!C31="","",'Input Data'!C31) | C31: =IF('Input Data'!D31="","",'Input Data'!D31) | D31: =IF('Input Data'!F31="","",'Input Data'!F31) | E31: =IF('Input Data'!E31="","",'Input Data'!E31) | F31: =IF('Input Data'!G31="","",'Input Data'!G31) | G31: =IF('Input Data'!J31="","",'Input Data'!J31) | H31: =IF('Input Data'!N31="Diterima","✓","") | I31: =IF('Input Data'!N31="Ditolak","✓","") | J31: =IF('Input Data'!O31="","",'Input Data'!O31)
A32: =IF('Input Data'!D32="","",'Input Data'!A32) | B32: =IF('Input Data'!C32="","",'Input Data'!C32) | C32: =IF('Input Data'!D32="","",'Input Data'!D32) | D32: =IF('Input Data'!F32="","",'Input Data'!F32) | E32: =IF('Input Data'!E32="","",'Input Data'!E32) | F32: =IF('Input Data'!G32="","",'Input Data'!G32) | G32: =IF('Input Data'!J32="","",'Input Data'!J32) | H32: =IF('Input Data'!N32="Diterima","✓","") | I32: =IF('Input Data'!N32="Ditolak","✓","") | J32: =IF('Input Data'!O32="","",'Input Data'!O32)
A34: HASIL PEMERIKSAAN BARANG KESELURUHAN
A35: Kondisi Kemasan : | E35: Baik | H35: Rusak
A36: Jumlah Barang : | D36: =IF('Input Data'!$J$18="","",IF(SUMPRODUCT(('Input Data'!$D$23:$D$32<>"")*('Input Data'!$G$23:$G$32<'Input Data'!$F$23:$F$32))=0,"✓","")) -> ✓ | E36: Lengkap | G36: =IF('Input Data'!$J$18="","",IF(SUMPRODUCT(('Input Data'!$D$23:$D$32<>"")*('Input Data'!$G$23:$G$32<'Input Data'!$F$23:$F$32))>0,"✓","")) | H36: Kurang
A37: Jenis dan Spesifikasi : | E37: Sesuai | H37: Tidak Sesuai | J37: Sebagian Tidak Sesuai
A38: Kondisi Barang : | E38: Baru & Baik | H38: Tidak Baik | J38: Bekas
A39: Diperlakukan Uji Fungsi* : | E39: Ya | H39: Tidak
A40: Hasil Uji Fungsi* : | E40: Lulus | H40: Tidak Lulus
A41: Kesesuaian Waktu Penyerahan : | D41: =IF('Input Data'!$J$19="tidak terlambat","✓","") | E41: Sesuai PO/RO | G41: =IF('Input Data'!$J$19="terlambat","✓","") | H41: Terlambat
A42: (*) jika dipersyaratkan
A44: GENERAL CHECKLIST DOCUMENTS
A45: (disesuaikan dengan Dokumen yang dipersyaratkan pada PO/Kontrak)
A46: No. | B46: Dokumen | G46: Hasil | I46: Catatan
G47: Yes | H47: No
A48: 1 | B48: Dokumen Pembelian (PO/RO) asli/salinan bertandatangan
...

Sheet Denda Keterlambatan
A1: Lampiran 6 – TKO No. B7-084/PHE52000/2025-S9-F005 · Revisi Ke-0
A2: PERTAMINA HULU ENERGI | C2: FORM PERHITUNGAN DENDA KETERLAMBATAN PENGIRIMAN BARANG
C5: Nomor : | E5: =IF('Input Data'!$J$15="","",'Input Data'!$J$15)
A6: Referensi Nomor GR | C6: =IF('Input Data'!$J$10="","",'Input Data'!$J$10) -> 5013916299
A7: Tanggal GR | C7: =IF('Input Data'!$J$11="","",'Input Data'!$J$11) -> NaN
A8: Nomor Kontrak/OA | C8: =IF('Input Data'!$D$6="","",'Input Data'!$D$6) -> 4720000471
A9: Nomor PO/RO | C9: =IF('Input Data'!$D$5="","",'Input Data'!$D$5) -> 4300096306
A10: ID Vendor | C10: =IF('Input Data'!$D$12="","",'Input Data'!$D$12) -> 144821
A11: Nama Vendor | C11: =IF('Input Data'!$D$13="","",'Input Data'!$D$13) -> PT. INTI PERKASA TEKNIK
A12: Email Vendor | C12: =IF('Input Data'!$D$15="","",'Input Data'!$D$15) -> iptek@indo.net.id
A13: Nomor Telp Vendor | C13: =IF('Input Data'!$D$16="","",'Input Data'!$D$16) -> 0761-839853
A14: Entitas Buyer | C14: =IF('Input Data'!$D$17="","",'Input Data'!$D$17) -> PT Pertamina EP Field Rantau
A15: Perihal | C15: ="Denda Keterlambatan Pengiriman Barang"&IF('Input Data'!$J$5="",""," – "&'Input Data'!$J$5) -> Denda Keterlambatan Pengiriman Barang – PEMENUHAN MATERIAL CUP PACKER PT PERTAMINA EP ZONA 1 FIELD RANTAU REF OA 4720000471
A17: Line No. | B17: Deskripsi Barang | C17: Qty | D17: Satuan | E17: KIMAP | G17: Harga Satuan (IDR) | I17: Jumlah Harga (IDR)
A18: =IF('Input Data'!B23="","",'Input Data'!B23) -> 1 | B18: =IF('Input Data'!D23="","",'Input Data'!D23) -> CUP PACKER, 7" X 2.7/8", 22-24# | C18: =IF('Input Data'!F23="","",'Input Data'!F23) -> 2 | D18: =IF('Input Data'!E23="","",'Input Data'!E23) -> PCS | E18: =IF('Input Data'!C23="","",'Input Data'!C23) -> B134900003 | G18: =IF('Input Data'!H23="","",'Input Data'!H23) -> 65865000 | I18: =IF('Input Data'!I23="","",'Input Data'!I23) -> 131730000
A19: =IF('Input Data'!B24="","",'Input Data'!B24) -> 2 | B19: =IF('Input Data'!D24="","",'Input Data'!D24) -> PCKR,REDRESS KIT,CUP,7,J55,5000,300 | C19: =IF('Input Data'!F24="","",'Input Data'!F24) -> 18 | D19: =IF('Input Data'!E24="","",'Input Data'!E24) -> PCS | E19: =IF('Input Data'!C24="","",'Input Data'!C24) -> Z66210004900 | G19: =IF('Input Data'!H24="","",'Input Data'!H24) -> 8500000 | I19: =IF('Input Data'!I24="","",'Input Data'!I24) -> 153000000
A20: =IF('Input Data'!B25="","",'Input Data'!B25) | B20: =IF('Input Data'!D25="","",'Input Data'!D25) | C20: =IF('Input Data'!F25="","",'Input Data'!F25) | D20: =IF('Input Data'!E25="","",'Input Data'!E25) | E20: =IF('Input Data'!C25="","",'Input Data'!C25) | G20: =IF('Input Data'!H25="","",'Input Data'!H25) | I20: =IF('Input Data'!I25="","",'Input Data'!I25)
A21: =IF('Input Data'!B26="","",'Input Data'!B26) | B21: =IF('Input Data'!D26="","",'Input Data'!D26) | C21: =IF('Input Data'!F26="","",'Input Data'!F26) | D21: =IF('Input Data'!E26="","",'Input Data'!E26) | E21: =IF('Input Data'!C26="","",'Input Data'!C26) | G21: =IF('Input Data'!H26="","",'Input Data'!H26) | I21: =IF('Input Data'!I26="","",'Input Data'!I26)
A22: =IF('Input Data'!B27="","",'Input Data'!B27) | B22: =IF('Input Data'!D27="","",'Input Data'!D27) | C22: =IF('Input Data'!F27="","",'Input Data'!F27) | D22: =IF('Input Data'!E27="","",'Input Data'!E27) | E22: =IF('Input Data'!C27="","",'Input Data'!C27) | G22: =IF('Input Data'!H27="","",'Input Data'!H27) | I22: =IF('Input Data'!I27="","",'Input Data'!I27)
A23: =IF('Input Data'!B28="","",'Input Data'!B28) | B23: =IF('Input Data'!D28="","",'Input Data'!D28) | C23: =IF('Input Data'!F28="","",'Input Data'!F28) | D23: =IF('Input Data'!E28="","",'Input Data'!E28) | E23: =IF('Input Data'!C28="","",'Input Data'!C28) | G23: =IF('Input Data'!H28="","",'Input Data'!H28) | I23: =IF('Input Data'!I28="","",'Input Data'!I28)
A24: =IF('Input Data'!B29="","",'Input Data'!B29) | B24: =IF('Input Data'!D29="","",'Input Data'!D29) | C24: =IF('Input Data'!F29="","",'Input Data'!F29) | D24: =IF('Input Data'!E29="","",'Input Data'!E29) | E24: =IF('Input Data'!C29="","",'Input Data'!C29) | G24: =IF('Input Data'!H29="","",'Input Data'!H29) | I24: =IF('Input Data'!I29="","",'Input Data'!I29)
A25: =IF('Input Data'!B30="","",'Input Data'!B30) | B25: =IF('Input Data'!D30="","",'Input Data'!D30) | C25: =IF('Input Data'!F30="","",'Input Data'!F30) | D25: =IF('Input Data'!E30="","",'Input Data'!E30) | E25: =IF('Input Data'!C30="","",'Input Data'!C30) | G25: =IF('Input Data'!H30="","",'Input Data'!H30) | I25: =IF('Input Data'!I30="","",'Input Data'!I30)
A26: =IF('Input Data'!B31="","",'Input Data'!B31) | B26: =IF('Input Data'!D31="","",'Input Data'!D31) | C26: =IF('Input Data'!F31="","",'Input Data'!F31) | D26: =IF('Input Data'!E31="","",'Input Data'!E31) | E26: =IF('Input Data'!C31="","",'Input Data'!C31) | G26: =IF('Input Data'!H31="","",'Input Data'!H31) | I26: =IF('Input Data'!I31="","",'Input Data'!I31)
A27: =IF('Input Data'!B32="","",'Input Data'!B32) | B27: =IF('Input Data'!D32="","",'Input Data'!D32) | C27: =IF('Input Data'!F32="","",'Input Data'!F32) | D27: =IF('Input Data'!E32="","",'Input Data'!E32) | E27: =IF('Input Data'!C32="","",'Input Data'!C32) | G27: =IF('Input Data'!H32="","",'Input Data'!H32) | I27: =IF('Input Data'!I32="","",'Input Data'!I32)
A28: Total | I28: =SUM(I18:I27) -> 284730000
A30: Berdasarkan tanggal penerimaan di Titik Penerimaan Barang (Delivery Point) :
A31: Line No. | B31: Deskripsi Barang | C31: Persyaratan PO/RO | F31: Penerimaan Warehouse | I31: Keterangan
C32: Qty | D32: Satuan | E32: Tanggal Jatuh Tempo | F32: Qty | G32: Satuan | H32: Tanggal Penerimaan
A33: =A18 -> 1 | B33: =B18 -> CUP PACKER, 7" X 2.7/8", 22-24# | C33: =C18 -> 2 | D33: =D18 -> PCS | E33: =IF('Input Data'!D23="","",IF('Input Data'!K23="",IF('Input Data'!$D$8="","",'Input Data'!$D$8),'Input Data'!K23)) -> NaN | F33: =IF('Input Data'!G23="","",'Input Data'!G23) -> 2 | G33: =D18 -> PCS | H33: =IF('Input Data'!D23="","",IF('Input Data'!L23="",IF('Input Data'!$J$7="","",'Input Data'!$J$7),'Input Data'!L23)) -> NaN | I33: =IF('Input Data'!M23="","",IF('Input Data'!M23>0,"Terlambat "&'Input Data'!M23&" hari","Tepat waktu")) -> #VALUE!
A34: =A19 -> 2 | B34: =B19 -> PCKR,REDRESS KIT,CUP,7,J55,5000,300 | C34: =C19 -> 18 | D34: =D19 -> PCS | E34: =IF('Input Data'!D24="","",IF('Input Data'!K24="",IF('Input Data'!$D$8="","",'Input Data'!$D$8),'Input Data'!K24)) -> NaN | F34: =IF('Input Data'!G24="","",'Input Data'!G24) -> 18 | G34: =D19 -> PCS | H34: =IF('Input Data'!D24="","",IF('Input Data'!L24="",IF('Input Data'!$J$7="","",'Input Data'!$J$7),'Input Data'!L24)) -> NaN | I34: =IF('Input Data'!M24="","",IF('Input Data'!M24>0,"Terlambat "&'Input Data'!M24&" hari","Tepat waktu")) -> #VALUE!
A35: =A20 | B35: =B20 | C35: =C20 | D35: =D20 | E35: =IF('Input Data'!D25="","",IF('Input Data'!K25="",IF('Input Data'!$D$8="","",'Input Data'!$D$8),'Input Data'!K25)) | F35: =IF('Input Data'!G25="","",'Input Data'!G25) | G35: =D20 | H35: =IF('Input Data'!D25="","",IF('Input Data'!L25="",IF('Input Data'!$J$7="","",'Input Data'!$J$7),'Input Data'!L25)) | I35: =IF('Input Data'!M25="","",IF('Input Data'!M25>0,"Terlambat "&'Input Data'!M25&" hari","Tepat waktu"))
A36: =A21 | B36: =B21 | C36: =C21 | D36: =D21 | E36: =IF('Input Data'!D26="","",IF('Input Data'!K26="",IF('Input Data'!$D$8="","",'Input Data'!$D$8),'Input Data'!K26)) | F36: =IF('Input Data'!G26="","",'Input Data'!G26) | G36: =D21 | H36: =IF('Input Data'!D26="","",IF('Input Data'!L26="",IF('Input Data'!$J$7="","",'Input Data'!$J$7),'Input Data'!L26)) | I36: =IF('Input Data'!M26="","",IF('Input Data'!M26>0,"Terlambat "&'Input Data'!M26&" hari","Tepat waktu"))
A37: =A22 | B37: =B22 | C37: =C22 | D37: =D22 | E37: =IF('Input Data'!D27="","",IF('Input Data'!K27="",IF('Input Data'!$D$8="","",'Input Data'!$D$8),'Input Data'!K27)) | F37: =IF('Input Data'!G27="","",'Input Data'!G27) | G37: =D22 | H37: =IF('Input Data'!D27="","",IF('Input Data'!L27="",IF('Input Data'!$J$7="","",'Input Data'!$J$7),'Input Data'!L27)) | I37: =IF('Input Data'!M27="","",IF('Input Data'!M27>0,"Terlambat "&'Input Data'!M27&" hari","Tepat waktu"))
A38: =A23 | B38: =B23 | C38: =C23 | D38: =D23 | E38: =IF('Input Data'!D28="","",IF('Input Data'!K28="",IF('Input Data'!$D$8="","",'Input Data'!$D$8),'Input Data'!K28)) | F38: =IF('Input Data'!G28="","",'Input Data'!G28) | G38: =D23 | H38: =IF('Input Data'!D28="","",IF('Input Data'!L28="",IF('Input Data'!$J$7="","",'Input Data'!$J$7),'Input Data'!L28)) | I38: =IF('Input Data'!M28="","",IF('Input Data'!M28>0,"Terlambat "&'Input Data'!M28&" hari","Tepat waktu"))
A39: =A24 | B39: =B24 | C39: =C24 | D39: =D24 | E39: =IF('Input Data'!D29="","",IF('Input Data'!K29="",IF('Input Data'!$D$8="","",'Input Data'!$D$8),'Input Data'!K29)) | F39: =IF('Input Data'!G29="","",'Input Data'!G29) | G39: =D24 | H39: =IF('Input Data'!D29="","",IF('Input Data'!L29="",IF('Input Data'!$J$7="","",'Input Data'!$J$7),'Input Data'!L29)) | I39: =IF('Input Data'!M29="","",IF('Input Data'!M29>0,"Terlambat "&'Input Data'!M29&" hari","Tepat waktu"))
A40: =A25 | B40: =B25 | C40: =C25 | D40: =D25 | E40: =IF('Input Data'!D30="","",IF('Input Data'!K30="",IF('Input Data'!$D$8="","",'Input Data'!$D$8),'Input Data'!K30)) | F40: =IF('Input Data'!G30="","",'Input Data'!G30) | G40: =D25 | H40: =IF('Input Data'!D30="","",IF('Input Data'!L30="",IF('Input Data'!$J$7="","",'Input Data'!$J$7),'Input Data'!L30)) | I40: =IF('Input Data'!M30="","",IF('Input Data'!M30>0,"Terlambat "&'Input Data'!M30&" hari","Tepat waktu"))
A41: =A26 | B41: =B26 | C41: =C26 | D41: =D26 | E41: =IF('Input Data'!D31="","",IF('Input Data'!K31="",IF('Input Data'!$D$8="","",'Input Data'!$D$8),'Input Data'!K31)) | F41: =IF('Input Data'!G31="","",'Input Data'!G31) | G41: =D26 | H41: =IF('Input Data'!D31="","",IF('Input Data'!L31="",IF('Input Data'!$J$7="","",'Input Data'!$J$7),'Input Data'!L31)) | I41: =IF('Input Data'!M31="","",IF('Input Data'!M31>0,"Terlambat "&'Input Data'!M31&" hari","Tepat waktu"))
A42: =A27 | B42: =B27 | C42: =C27 | D42: =D27 | E42: =IF('Input Data'!D32="","",IF('Input Data'!K32="",IF('Input Data'!$D$8="","",'Input Data'!$D$8),'Input Data'!K32)) | F42: =IF('Input Data'!G32="","",'Input Data'!G32) | G42: =D27 | H42: =IF('Input Data'!D32="","",IF('Input Data'!L32="",IF('Input Data'!$J$7="","",'Input Data'!$J$7),'Input Data'!L32)) | I42: =IF('Input Data'!M32="","",IF('Input Data'!M32>0,"Terlambat "&'Input Data'!M32&" hari","Tepat waktu"))
A44: Denda/sanksi atas ketidaksesuaian Waktu Penerimaan Barang:
A45: Perhitungan denda dihitung berdasarkan ketentuan yang diatur di dalam Outline Agreement (OA), Release Order (RO), dan Purchase Order (PO)
...

Sheet Daftar
A1: Daftar Dokumen (Lampiran 8 TKO B7-084)
A2: Dokumen Pembelian (PO/RO) asli/salinan bertandatangan
A3: Surat Jalan Asli (dengan referensi nomor PO/RO)
A4: Sertifikat Barang / dokumen pendukung sesuai PO/RO
A5: Material Mill Certificate
A6: Vendor Warranty
A7: Vendor Quality Assurance (Jaminan Kualitas)
A8: API Certificate
A9: Certificate of Compliance/Conformance
A10: Pressure Test Report
A11: Chemical Analysis
A12: Functional Test Report
... A24: Dokumen Kepabeanan (Incoterm DAP)
